<?xml version="1.0" ?>
<!-- This URDF was automatically created by SolidWorks to URDF Exporter! Originally created by Stephen Brawner (brawner@gmail.com) 
     Commit Version: 1.6.0-4-g7f85cfe  Build Version: 1.6.7995.38578
     For more information, please see http://wiki.ros.org/sw_urdf_exporter -->
<robot
  name="manipulator" xmlns:xacro="http://ros.org/wiki/xacro">

  <xacro:macro name="body_color">
    <visual>
    <material>
        <ambient>0.8 0.558823529411765 0.1 1</ambient>
        <diffuse>0.8 0.558823529411765 0.1 1</diffuse>
        <specular>0.1 0.1 0.1 1</specular>
        <emissive>0 0 0 0</emissive>
    </material>
    </visual>
  </xacro:macro>

  # Add this before base link
  <link name="dummy_link"></link>

  <link
    name="base_link">
    <inertial>
      <origin
        xyz="4.9107E-05 4.9107E-05 0.074575"
        rpy="0 0 0" />
      <mass
        value="1307.2" />
      <inertia
        ixx="63.83"
        ixy="0.006149"
        ixz="-0.014068"
        iyy="63.795"
        iyz="-0.014068"
        izz="98.574" />
    </inertial>
    <visual>
      <origin
        xyz="0 0 0"
        rpy="0 0 0" />
      <geometry>
        <mesh
          filename="package://manipulator/meshes/base_link.STL" />
      </geometry>
      <material
        name="">
        <color
          rgba="0.52941 0.54902 0.54902 1" />
      </material>
    </visual>
    <collision>
      <origin
        xyz="0 0 0"
        rpy="0 0 0" />
      <geometry>
        <mesh
          filename="package://manipulator/meshes/base_link.STL" />
      </geometry>
    </collision>
  </link>

  # Add this after base link
  <joint name="dummy_joint" type="fixed">
      <origin rpy="-1.5708 0 0" xyz="0 0 0" />
      <parent link="dummy_link"/>
      <child link="base_link"/>
  </joint>

  <link
    name="steering_link_1">
    <inertial>
      <origin
        xyz="0.042479 1.1102E-16 -0.062687"
        rpy="0 0 0" />
      <mass
        value="4.8522" />
      <inertia
        ixx="0.013585"
        ixy="1.6486E-18"
        ixz="0.0021076"
        iyy="0.018007"
        iyz="-2.869E-18"
        izz="0.0085973" />
    </inertial>
    <visual>
      <origin
        xyz="0 0 0"
        rpy="0 0 0" />
      <geometry>
        <mesh
          filename="package://manipulator/meshes/steering_link_1.STL" />
      </geometry>
      <material
        name="">
        <color
          rgba="0.52941 0.54902 0.54902 1" />
      </material>
    </visual>
    <collision>
      <origin
        xyz="0 0 0"
        rpy="0 0 0" />
      <geometry>
        <mesh
          filename="package://manipulator/meshes/steering_link_1.STL" />
      </geometry>
    </collision>
  </link>
  <joint
    name="steering_joint_1"
    type="revolute">
    <origin
      xyz="-0.275 0.105 0.3"
      rpy="1.5708 1.5708 0" />
    <parent
      link="base_link" />
    <child
      link="steering_link_1" />
    <axis
      xyz="0 0 1" />
    <limit
      lower="-3.1416"
      upper="3.1416"
      effort="0"
      velocity="0" />
  </joint>
  <link
    name="wheel_1">
    <inertial>
      <origin
        xyz="-5.5511E-17 0.019674 -8.3267E-17"
        rpy="0 0 0" />
      <mass
        value="12.04" />
      <inertia
        ixx="0.043182"
        ixy="8.5859E-18"
        ixz="-1.8246E-17"
        iyy="0.074681"
        iyz="1.1303E-17"
        izz="0.043182" />
    </inertial>
    <visual>
      <origin
        xyz="0 0 0"
        rpy="0 0 0" />
      <geometry>
        <mesh
          filename="package://manipulator/meshes/wheel_1.STL" />
      </geometry>
      <material
        name="">
        <color
          rgba="0.52941 0.54902 0.54902 1" />
      </material>
    </visual>
    <collision>
      <origin
        xyz="0 0 0"
        rpy="0 0 0" />
      <geometry>
        <mesh
          filename="package://manipulator/meshes/wheel_1.STL" />
      </geometry>
    </collision>
  </link>
  <joint
    name="wheel_joint_1"
    type="continuous">
    <origin
      xyz="0 0 -0.14"
      rpy="0 0 1.5708" />
    <parent
      link="steering_link_1" />
    <child
      link="wheel_1" />
    <axis
      xyz="0 1 0" />
    <limit
      effort="100"
      velocity="100" />
  </joint>
  <link
    name="steering_link_2">
    <inertial>
      <origin
        xyz="0.042479 5.5511E-17 -0.062687"
        rpy="0 0 0" />
      <mass
        value="4.8522" />
      <inertia
        ixx="0.013585"
        ixy="7.2512E-19"
        ixz="0.0021076"
        iyy="0.018007"
        iyz="-1.1739E-18"
        izz="0.0085973" />
    </inertial>
    <visual>
      <origin
        xyz="0 0 0"
        rpy="0 0 0" />
      <geometry>
        <mesh
          filename="package://manipulator/meshes/steering_link_2.STL" />
      </geometry>
      <material
        name="">
        <color
          rgba="0.52941 0.54902 0.54902 1" />
      </material>
    </visual>
    <collision>
      <origin
        xyz="0 0 0"
        rpy="0 0 0" />
      <geometry>
        <mesh
          filename="package://manipulator/meshes/steering_link_2.STL" />
      </geometry>
    </collision>
  </link>
  <joint
    name="steering_joint_2"
    type="continuous">
    <origin
      xyz="-0.275 0.105 -0.3"
      rpy="1.5708 -1.5708 0" />
    <parent
      link="base_link" />
    <child
      link="steering_link_2" />
    <axis
      xyz="0 0 1" />
    <limit
      lower="-3.1416"
      upper="3.1416"
      effort="100"
      velocity="100" />
  </joint>
  <link
    name="wheel_2">
    <inertial>
      <origin
        xyz="5.5511E-17 0.019674 -5.5511E-17"
        rpy="0 0 0" />
      <mass
        value="12.04" />
      <inertia
        ixx="0.043182"
        ixy="-2.9671E-18"
        ixz="1.0408E-17"
        iyy="0.074681"
        iyz="7.6252E-18"
        izz="0.043182" />
    </inertial>
    <visual>
      <origin
        xyz="0 0 0"
        rpy="0 0 0" />
      <geometry>
        <mesh
          filename="package://manipulator/meshes/wheel_2.STL" />
      </geometry>
      <material
        name="">
        <color
          rgba="0.52941 0.54902 0.54902 1" />
      </material>
    </visual>
    <collision>
      <origin
        xyz="0 0 0"
        rpy="0 0 0" />
      <geometry>
        <mesh
          filename="package://manipulator/meshes/wheel_2.STL" />
      </geometry>
    </collision>
  </link>
  <joint
    name="wheel_joint_2"
    type="continuous">
    <origin
      xyz="0 0 -0.14"
      rpy="0 0.56883 1.5708" />
    <parent
      link="steering_link_2" />
    <child
      link="wheel_2" />
    <axis
      xyz="0 1 0" />
    <limit
      effort="100"
      velocity="100" />
  </joint>
  <link
    name="steering_link_3">
    <inertial>
      <origin
        xyz="0.092479 0.0375 -0.027687"
        rpy="0 0 0" />
      <mass
        value="4.8522" />
      <inertia
        ixx="0.013585"
        ixy="7.563E-19"
        ixz="0.0021076"
        iyy="0.018007"
        iyz="-2.9107E-18"
        izz="0.0085973" />
    </inertial>
    <visual>
      <origin
        xyz="0 0 0"
        rpy="0 0 0" />
      <geometry>
        <mesh
          filename="package://manipulator/meshes/steering_link_3.STL" />
      </geometry>
      <material
        name="">
        <color
          rgba="0.52941 0.54902 0.54902 1" />
      </material>
    </visual>
    <collision>
      <origin
        xyz="0 0 0"
        rpy="0 0 0" />
      <geometry>
        <mesh
          filename="package://manipulator/meshes/steering_link_3.STL" />
      </geometry>
    </collision>
  </link>
  <joint
    name="steering_joint_3"
    type="fixed">
    <origin
      xyz="0.3125 0.14 -0.35"
      rpy="1.5708 -1.5708 0" />
    <parent
      link="base_link" />
    <child
      link="steering_link_3" />
    <axis
      xyz="0 0 0" />
  </joint>
  <link
    name="wheel_3">
    <inertial>
      <origin
        xyz="1.1102E-16 -0.030326 1.6653E-16"
        rpy="0 0 0" />
      <mass
        value="12.04" />
      <inertia
        ixx="0.043182"
        ixy="-1.735E-18"
        ixz="-1.7347E-17"
        iyy="0.074681"
        iyz="-2.5561E-18"
        izz="0.043182" />
    </inertial>
    <visual>
      <origin
        xyz="0 0 0"
        rpy="0 0 0" />
      <geometry>
        <mesh
          filename="package://manipulator/meshes/wheel_3.STL" />
      </geometry>
      <material
        name="">
        <color
          rgba="0.52941 0.54902 0.54902 1" />
      </material>
    </visual>
    <collision>
      <origin
        xyz="0 0 0"
        rpy="0 0 0" />
      <geometry>
        <mesh
          filename="package://manipulator/meshes/wheel_3.STL" />
      </geometry>
    </collision>
  </link>
  <joint
    name="wheel_joint_3"
    type="continuous">
    <origin
      xyz="0 0.0375 -0.105"
      rpy="0 0.58362 1.5708" />
    <parent
      link="steering_link_3" />
    <child
      link="wheel_3" />
    <axis
      xyz="0 1 0" />
    <limit
      effort="100"
      velocity="100" />
  </joint>
  <link
    name="steering_link_4">
    <inertial>
      <origin
        xyz="0.092479 0.0375 -0.027687"
        rpy="0 0 0" />
      <mass
        value="4.8522" />
      <inertia
        ixx="0.013585"
        ixy="1.0431E-18"
        ixz="0.0021076"
        iyy="0.018007"
        iyz="1.0299E-18"
        izz="0.0085973" />
    </inertial>
    <visual>
      <origin
        xyz="0 0 0"
        rpy="0 0 0" />
      <geometry>
        <mesh
          filename="package://manipulator/meshes/steering_link_4.STL" />
      </geometry>
      <material
        name="">
        <color
          rgba="0.52941 0.54902 0.54902 1" />
      </material>
    </visual>
    <collision>
      <origin
        xyz="0 0 0"
        rpy="0 0 0" />
      <geometry>
        <mesh
          filename="package://manipulator/meshes/steering_link_4.STL" />
      </geometry>
    </collision>
  </link>
  <joint
    name="steering_joint_4"
    type="fixed">
    <origin
      xyz="0.2375 0.14 0.35"
      rpy="1.5708 1.5708 0" />
    <parent
      link="base_link" />
    <child
      link="steering_link_4" />
    <axis
      xyz="0 0 0" />
  </joint>
  <link
    name="wheel_4">
    <inertial>
      <origin
        xyz="0 -0.030326 0"
        rpy="0 0 0" />
      <mass
        value="12.04" />
      <inertia
        ixx="0.043182"
        ixy="1.2938E-17"
        ixz="-2.4229E-17"
        iyy="0.074681"
        iyz="-1.2277E-17"
        izz="0.043182" />
    </inertial>
    <visual>
      <origin
        xyz="0 0 0"
        rpy="0 0 0" />
      <geometry>
        <mesh
          filename="package://manipulator/meshes/wheel_4.STL" />
      </geometry>
      <material
        name="">
        <color
          rgba="0.52941 0.54902 0.54902 1" />
      </material>
    </visual>
    <collision>
      <origin
        xyz="0 0 0"
        rpy="0 0 0" />
      <geometry>
        <mesh
          filename="package://manipulator/meshes/wheel_4.STL" />
      </geometry>
    </collision>
  </link>
  <joint
    name="wheel_joint_"
    type="continuous">
    <origin
      xyz="0 0.0375 -0.105"
      rpy="0 0 1.5708" />
    <parent
      link="steering_link_4" />
    <child
      link="wheel_4" />
    <axis
      xyz="0 1 0" />
    <limit
      effort="100"
      velocity="100" />
  </joint>
  <link
    name="lidar">
    <inertial>
      <origin
        xyz="0 2.7756E-17 0.04975"
        rpy="0 0 0" />
      <mass
        value="15.601" />
      <inertia
        ixx="0.037726"
        ixy="-4.7022E-35"
        ixz="-6.5636E-19"
        iyy="0.037726"
        iyz="-1.0109E-34"
        izz="0.04969" />
    </inertial>
    <visual>
      <origin
        xyz="0 0 0"
        rpy="0 0 0" />
      <geometry>
        <mesh
          filename="package://manipulator/meshes/lidar.STL" />
      </geometry>
      <material
        name="">
        <color
          rgba="0.52941 0.54902 0.54902 1" />
      </material>
    </visual>
    <collision>
      <origin
        xyz="0 0 0"
        rpy="0 0 0" />
      <geometry>
        <mesh
          filename="package://manipulator/meshes/lidar.STL" />
      </geometry>
    </collision>
  </link>
  <joint
    name="lidar_joint"
    type="fixed">
    <origin
      xyz="-0.19908 -0.25 0.20045"
      rpy="1.5708 0 0" />
    <parent
      link="base_link" />
    <child
      link="lidar" />
    <axis
      xyz="0 0 0" />
  </joint>
  <link
    name="link_1">
    <inertial>
      <origin
        xyz="-0.059024 -0.0039351 0.084778"
        rpy="0 0 0" />
      <mass
        value="18.624" />
      <inertia
        ixx="0.09669"
        ixy="-0.0048378"
        ixz="0.073637"
        iyy="0.19228"
        iyz="0.0043722"
        izz="0.13132" />
    </inertial>
    <visual>
      <origin
        xyz="0 0 0"
        rpy="0 0 0" />
      <geometry>
        <mesh
          filename="package://manipulator/meshes/link_1.STL" />
      </geometry>
      <material
        name="">
        <color
          rgba="0.52941 0.54902 0.54902 1" />
      </material>
    </visual>
    <collision>
      <origin
        xyz="0 0 0"
        rpy="0 0 0" />
      <geometry>
        <mesh
          filename="package://manipulator/meshes/link_1.STL" />
      </geometry>
    </collision>
  </link>
  <joint
    name="link_joint_1"
    type="continuous">
    <origin
      xyz="0 -0.334 0"
      rpy="1.5708 -1.5708 0" />
    <parent
      link="base_link" />
    <child
      link="link_1" />
    <axis
      xyz="0 0 1" />
    <limit
      lower="-3.1416"
      upper="3.1416"
      effort="100"
      velocity="100" />
  </joint>
  <link
    name="link_2">
    <inertial>
      <origin
        xyz="-0.14996 -0.0094082 0.036311"
        rpy="0 0 0" />
      <mass
        value="8.2062" />
      <inertia
        ixx="0.0053635"
        ixy="-0.0019393"
        ixz="-0.00037798"
        iyy="0.14549"
        iyz="-0.00015886"
        izz="0.14856" />
    </inertial>
    <visual>
      <origin
        xyz="0 0 0"
        rpy="0 0 0" />
      <geometry>
        <mesh
          filename="package://manipulator/meshes/link_2.STL" />
      </geometry>
      <material
        name="">
        <color
          rgba="0.52941 0.54902 0.54902 1" />
      </material>
    </visual>
    <collision>
      <origin
        xyz="0 0 0"
        rpy="0 0 0" />
      <geometry>
        <mesh
          filename="package://manipulator/meshes/link_2.STL" />
      </geometry>
    </collision>
  </link>
  <joint
    name="joint_link_2"
    type="continuous">
    <origin
      xyz="-0.15 0 0.16"
      rpy="-1.5708 1.5433 0" />
    <parent
      link="link_1" />
    <child
      link="link_2" />
    <axis
      xyz="0 0 1" />
    <limit
      lower="-3.1416"
      upper="3.1416"
      effort="100"
      velocity="100" />
  </joint>
  <link
    name="link_3">
    <inertial>
      <origin
        xyz="0.043583 -0.043578 0.019176"
        rpy="0 0 0" />
      <mass
        value="11.283" />
      <inertia
        ixx="0.060031"
        ixy="0.01534"
        ixz="0.0045951"
        iyy="0.026161"
        iyz="-0.014572"
        izz="0.057655" />
    </inertial>
    <visual>
      <origin
        xyz="0 0 0"
        rpy="0 0 0" />
      <geometry>
        <mesh
          filename="package://manipulator/meshes/link_3.STL" />
      </geometry>
      <material
        name="">
        <color
          rgba="0.52941 0.54902 0.54902 1" />
      </material>
    </visual>
    <collision>
      <origin
        xyz="0 0 0"
        rpy="0 0 0" />
      <geometry>
        <mesh
          filename="package://manipulator/meshes/link_3.STL" />
      </geometry>
    </collision>
  </link>
  <joint
    name="joint_link_3"
    type="continuous">
    <origin
      xyz="-0.35 0 0"
      rpy="-1.5708 1.2274 1.9986" />
    <parent
      link="link_2" />
    <child
      link="link_3" />
    <axis
      xyz="0.94161 0.3367 0" />
    <limit
      lower="-3.1416"
      upper="3.1416"
      effort="100"
      velocity="100" />
  </joint>
  <link
    name="link_4">
    <inertial>
      <origin
        xyz="0.034716 -0.097082 -0.043628"
        rpy="0 0 0" />
      <mass
        value="4.5488" />
      <inertia
        ixx="0.010246"
        ixy="0.0016632"
        ixz="0.00097077"
        iyy="0.0061178"
        iyz="-0.002558"
        izz="0.010838" />
    </inertial>
    <visual>
      <origin
        xyz="0 0 0"
        rpy="0 0 0" />
      <geometry>
        <mesh
          filename="package://manipulator/meshes/link_4.STL" />
      </geometry>
      <material
        name="">
        <color
          rgba="0.52941 0.54902 0.54902 1" />
      </material>
    </visual>
    <collision>
      <origin
        xyz="0 0 0"
        rpy="0 0 0" />
      <geometry>
        <mesh
          filename="package://manipulator/meshes/link_4.STL" />
      </geometry>
    </collision>
  </link>
  <joint
    name="joint_link_4"
    type="continuous">
    <origin
      xyz="0.095279 -0.18329 -0.037744"
      rpy="2.382 0.28812 -2.5704" />
    <parent
      link="link_3" />
    <child
      link="link_4" />
    <axis
      xyz="0.31008 -0.86717 -0.3897" />
    <limit
      lower="-3.1416"
      upper="3.1416"
      effort="100"
      velocity="100" />
  </joint>
  <link
    name="link_5">
    <inertial>
      <origin
        xyz="-0.016408 0.036444 -0.042263"
        rpy="0 0 0" />
      <mass
        value="2.6241" />
      <inertia
        ixx="0.0027467"
        ixy="0.00016692"
        ixz="-0.00018608"
        iyy="0.0024334"
        iyz="0.00042524"
        izz="0.0023081" />
    </inertial>
    <visual>
      <origin
        xyz="0 0 0"
        rpy="0 0 0" />
      <geometry>
        <mesh
          filename="package://manipulator/meshes/link_5.STL" />
      </geometry>
      <material
        name="">
        <color
          rgba="0.52941 0.54902 0.54902 1" />
      </material>
    </visual>
    <collision>
      <origin
        xyz="0 0 0"
        rpy="0 0 0" />
      <geometry>
        <mesh
          filename="package://manipulator/meshes/link_5.STL" />
      </geometry>
    </collision>
  </link>
  <joint
    name="joint_link_5"
    type="continuous">
    <origin
      xyz="0.048932 -0.13684 -0.061495"
      rpy="2.0077 0.30375 -2.6698" />
    <parent
      link="link_4" />
    <child
      link="link_5" />
    <axis
      xyz="0.93402 0.35433 -0.045258" />
    <limit
      lower="-3.1416"
      upper="3.1416"
      effort="100"
      velocity="100" />
  </joint>
  <link
    name="end_effector">
    <inertial>
      <origin
        xyz="-3.8515E-11 3.9888E-07 -0.066073"
        rpy="0 0 0" />
      <mass
        value="2.0243" />
      <inertia
        ixx="0.0058599"
        ixy="2.2551E-17"
        ixz="2.0837E-13"
        iyy="0.0058599"
        iyz="3.7145E-08"
        izz="0.0062173" />
    </inertial>
    <visual>
      <origin
        xyz="0 0 0"
        rpy="0 0 0" />
      <geometry>
        <mesh
          filename="package://manipulator/meshes/end_effector.STL" />
      </geometry>
      <material
        name="">
        <color
          rgba="0.52941 0.54902 0.54902 1" />
      </material>
    </visual>
    <collision>
      <origin
        xyz="0 0 0"
        rpy="0 0 0" />
      <geometry>
        <mesh
          filename="package://manipulator/meshes/end_effector.STL" />
      </geometry>
    </collision>
  </link>
  <joint
    name="end_effector_joint"
    type="continuous">
    <origin
      xyz="-0.026229 0.059004 -0.068314"
      rpy="0.55846 -0.54094 1.0999" />
    <parent
      link="link_5" />
    <child
      link="end_effector" />
    <axis
      xyz="0 0 1" />
    <limit
      lower="-3.1416"
      upper="3.1416"
      effort="100"
      velocity="100" />
  </joint>

# Add color
  <gazebo reference="base_link">
      <xacro:body_color />
  </gazebo>

# Add controller
 <ros2_control name="GazeboSystem" type="system">
    <hardware>
        <plugin>gazebo_ros2_control/GazeboSystem</plugin>
    </hardware>

   # Velocity Controllers

    <joint name="wheel_joint_1">
          <command_interface name="velocity">
              <param name="min">-1000.0</param>
              <param name="max">1000.0</param>
          </command_interface>
          <state_interface name="position"/>
          <state_interface name="velocity"/>
      </joint>

    <joint name="wheel_joint_2">
        <command_interface name="velocity">
            <param name="min">-1000.0</param>
            <param name="max">1000.0</param>
        </command_interface>
        <state_interface name="position"/>
        <state_interface name="velocity"/>
    </joint>

    <joint name="wheel_joint_3">
        <command_interface name="velocity">
            <param name="min">-1000.0</param>
            <param name="max">1000.0</param>
        </command_interface>
        <state_interface name="position"/>
        <state_interface name="velocity"/>
    </joint>

    <joint name="wheel_joint_">
        <command_interface name="velocity">
            <param name="min">-1000.0</param>
            <param name="max">1000.0</param>
        </command_interface>
        <state_interface name="position"/>
        <state_interface name="velocity"/>
    </joint>


   <joint name="steering_joint_1">
        <command_interface name="velocity">
            <param name="min">-1000.0</param>
            <param name="max">1000.0</param>
        </command_interface>
        <state_interface name="position"/>
        <state_interface name="velocity"/>
    </joint>

    <joint name="steering_joint_2">
        <command_interface name="velocity">
            <param name="min">-1000.0</param>
            <param name="max">1000.0</param>
        </command_interface>
        <state_interface name="position"/>
        <state_interface name="velocity"/>
    </joint>

    <joint name="link_joint_1">
        <command_interface name="velocity">
            <param name="min">-1000.0</param>
            <param name="max">1000.0</param>
        </command_interface>
        <state_interface name="position"/>
        <state_interface name="velocity"/>
    </joint>

    <joint name="joint_link_2">
        <command_interface name="velocity">
            <param name="min">-1000.0</param>
            <param name="max">1000.0</param>
        </command_interface>
        <state_interface name="position"/>
        <state_interface name="velocity"/>
    </joint>

    <joint name="joint_link_3">
        <command_interface name="velocity">
            <param name="min">-1000.0</param>
            <param name="max">1000.0</param>
        </command_interface>
        <state_interface name="position"/>
        <state_interface name="velocity"/>
    </joint>

    <joint name="joint_link_4">
        <command_interface name="velocity">
            <param name="min">-1000.0</param>
            <param name="max">1000.0</param>
        </command_interface>
        <state_interface name="position"/>
        <state_interface name="velocity"/>
    </joint>

    <joint name="joint_link_5">
        <command_interface name="velocity">
            <param name="min">-1000.0</param>
            <param name="max">1000.0</param>
        </command_interface>
        <state_interface name="position"/>
        <state_interface name="velocity"/>
    </joint>

    <joint name="end_effector_joint">
        <command_interface name="velocity">
            <param name="min">-1000.0</param>
            <param name="max">1000.0</param>
        </command_interface>
        <state_interface name="position"/>
        <state_interface name="velocity"/>
    </joint>


   # Position Controller
    <joint name="steering_joint_1">
      <command_interface name="position">
          <param name="min">-3.14</param>
          <param name="max">3.14</param>
      </command_interface>
      <state_interface name="position"/>
      <state_interface name="velocity"/>
    </joint>

    <joint name="steering_joint_2">
        <command_interface name="position">
            <param name="min">-3.14</param>
            <param name="max">3.14</param>
        </command_interface>
        <state_interface name="position"/>
        <state_interface name="velocity"/>
    </joint>

    <joint name="link_joint_1">
      <command_interface name="position">
          <param name="min">-3.14</param>
          <param name="max">3.14</param>
      </command_interface>
      <state_interface name="position"/>
      <state_interface name="velocity"/>
    </joint>

    <joint name="joint_link_2">
        <command_interface name="position">
            <param name="min">-3.14</param>
            <param name="max">3.14</param>
        </command_interface>
        <state_interface name="position"/>
        <state_interface name="velocity"/>
    </joint>

    <joint name="joint_link_3">
      <command_interface name="position">
          <param name="min">-3.14</param>
          <param name="max">3.14</param>
      </command_interface>
      <state_interface name="position"/>
      <state_interface name="velocity"/>
    </joint>

    <joint name="joint_link_4">
        <command_interface name="position">
            <param name="min">-3.14</param>
            <param name="max">3.14</param>
        </command_interface>
        <state_interface name="position"/>
        <state_interface name="velocity"/>
    </joint>

   <joint name="joint_link_5">
      <command_interface name="position">
          <param name="min">-3.14</param>
          <param name="max">3.14</param>
      </command_interface>
      <state_interface name="position"/>
      <state_interface name="velocity"/>
    </joint>

    <joint name="end_effector_joint">
        <command_interface name="position">
            <param name="min">-3.14</param>
            <param name="max">3.14</param>
        </command_interface>
        <state_interface name="position"/>
        <state_interface name="velocity"/>
    </joint>

    #Controller end
  </ros2_control>
  <gazebo>
    <plugin filename="libgazebo_ros2_control.so" name="gazebo_ros2_control">
        <parameters>$(find manipulator)/config/control.yaml</parameters>
    </plugin>
  </gazebo>

  # LIDAR
  <gazebo reference="lidar">
  <sensor name="lidar" type="ray">
    <pose>0.0 0.0 0.0 0 0 0</pose>
    <always_on>true</always_on>
    <visualize>true</visualize>
    <update_rate>5</update_rate>
    <ray>
      <scan>
        <horizontal>
          <samples>360</samples>
          <resolution>1.00000</resolution>
          <min_angle>0.000000</min_angle>
          <max_angle>6.280000</max_angle>
        </horizontal>
      </scan>
      <range>
        <min>0.120000</min>
        <max>3.5</max>
        <resolution>0.015000</resolution>
      </range>
      <noise>
        <type>gaussian</type>
        <mean>0.0</mean>
        <stddev>0.01</stddev>
      </noise>
    </ray>
    <plugin name="scan" filename="libgazebo_ros_ray_sensor.so">
      <ros>
        <remapping>~/out:=scan</remapping>
      </ros>
      <output_type>sensor_msgs/LaserScan</output_type>
      <frame_name>add_name_of_your_link</frame_name>
    </plugin>
  </sensor>
  </gazebo>

  # IMU
  <gazebo reference="base_link">
  <gravity>true</gravity>
  <sensor name="imu_sensor" type="imu">
    <always_on>true</always_on>
    <update_rate>100</update_rate>
    <visualize>true</visualize>
    <topic>__default_topic__</topic>
    <plugin filename="libgazebo_ros_imu_sensor.so" name="imu_plugin">
      <topicName>imu</topicName>
      <bodyName>base_link</bodyName>
      <updateRateHZ>10.0</updateRateHZ>
      <gaussianNoise>0.0</gaussianNoise>
      <xyzOffset>0 0 0</xyzOffset>
      <rpyOffset>0 0 0</rpyOffset>
      <frameName>base_link</frameName>
      <initialOrientationAsReference>false</initialOrientationAsReference>
    </plugin>
    <pose>0 0 0 0 0 0</pose>
  </sensor>
</gazebo>

</robot>